Workbook

Sheet README
A1: Costco Membership Pricing: Research Dataset and Model
A2: BFIN515 Economic Analysis, Assignment 2. Question: how does Costco's membership fee affect membership demand, and what fee maximizes estimated membership revenue?
A4: TABS
A5: Panel_Data | B5: FY2014-FY2025 panel: fees, paid/Executive members, cardholders, renewal rates, fee income, warehouses, plus derived growth and log-difference variables.
A6: Fee_History | B6: U.S./Canada fee schedule and the size/timing of each increase.
A7: Event_Study | B7: Growth and renewal behavior around the 2017 and 2024 increases; implied arc elasticity.
A8: Regression | B8: Log-difference LINEST models of paid-member growth on fee changes and warehouse growth.
A9: Revenue_Sim | B9: Revenue vs. fee under three demand shapes, closed-form optimum for linear demand, sensitivity table and chart.
A10: Sources | B10: 10-K links and items still to verify.
A12: COLOR LEGEND
A13: Blue text | B13: Hardcoded input taken from a filing or stated as an assumption.
A14: Black text | B14: Formula.
A15: Green text | B15: Formula pulling from another tab.
A16: Orange fill | B16: Not verified against a filing in this build; check before citing.
A17: Light-yellow fill | B17: Estimate derived from a rounded reported percentage (Executive members FY2014-FY2019).
A18: Yellow fill | B18: Key assumption or user override cell: change these to test scenarios.
A20: KEY CAVEATS
A21: 1 | B21: Only two fee increases (2017, 2024) fall in the sample, so any elasticity estimate has very low statistical power.
A22: 2 | B22: Paid-member counts are worldwide; fee changes applied to the U.S. and Canada only, diluting the measured demand response.
A23: 3 | B23: Membership growth is driven heavily by new warehouse openings; the regression controls for this but the event study does not.
A24: 4 | B24: FY2020 counting-method change (+1.3M paid members) is adjusted for in growth rates only.
A25: 5 | B25: The revenue-maximizing fee depends on extrapolating demand far beyond the observed $55-$65 range; treat Revenue_Sim as scenario analysis.
A26: 6 | B26: Possible extensions: add CPI or real disposable income from FRED as a control; add quarterly 10-Q data; add FY2026 once the 10-K is filed.

Sheet Panel_Data
A1: Costco Membership Panel, FY2014-FY2025
A2: Units: member counts in thousands; fee income in $ millions; fees in US$ (U.S./Canada Gold Star and Executive). Blue = hardcoded from filings, black = formula, orange fill = NOT verified against a filing in this build, light-yellow fill = estimate derived from a rounded percentage.
A3: Fiscal year ends on the Sunday nearest Aug 31. FY2017 and FY2023 are 53-week years. Full notes below the table; sources on the Sources tab.
A5: Fiscal year | B5: FY end date | C5: Weeks in FY | D5: Gold Star fee, start of FY ($) | E5: Gold Star fee, end of FY ($) | F5: Executive fee, end of FY ($) | G5: Total paid members (000s) | H5: Business incl. affiliates (000s) | I5: Gold Star (000s) = Paid - Business | J5: Executive share of paid (reported, rounded) | K5: Executive members (000s) | L5: Executive share of paid (calc.) | M5: Total cardholders (000s) | N5: Household / other cards (000s) = Cardholders - Paid | O5: Renewal rate, U.S. & Canada | P5: Renewal rate, worldwide | Q5: Membership fee income ($M) | R5: Warehouses at FY end | S5: Count-method adjustment (000s) | T5: Fee income per paid member ($) | U5: Paid members per warehouse (000s) | V5: Paid-member growth, % (method-adjusted) | W5: Delta ln(paid members), adj. | X5: Delta ln(GS fee), t-1 | Y5: Delta ln(GS fee), t | Z5: Delta ln(warehouses) | AA5: Delta renewal rate, U.S. & Canada (pts) | AB5: Primary source
A6: 2014 | B6: 41882 | C6: 52 | D6: 55 | E6: 55 | F6: 110 | G6: 42000 | H6: 10400 | I6: =G6-H6 -> 31600 | J6: 0.39 | K6: =J6*G6 -> 16380 | L6: =K6/G6 -> 0.39 | M6: 76400 | N6: =M6-G6 -> 34400 | O6: n/a | P6: n/a | Q6: 2428 | R6: 663 | S6: 0 | T6: =Q6*1000/G6 -> 57.809524 | U6: =G6/R6 -> 63.348416 | V6: n/a | W6: n/a | X6: n/a | Y6: n/a | Z6: n/a | AA6: n/a | AB6: FY2016 10-K (members); fee income & warehouses from memory - VERIFY
A7: 2015 | B7: 42246 | C7: 52 | D7: 55 | E7: 55 | F7: 110 | G7: 44600 | H7: 10600 | I7: =G7-H7 -> 34000 | J7: 0.39 | K7: =J7*G7 -> 17394 | L7: =K7/G7 -> 0.39 | M7: 81300 | N7: =M7-G7 -> 36700 | O7: n/a | P7: n/a | Q7: 2533 | R7: 686 | S7: 0 | T7: =Q7*1000/G7 -> 56.793722 | U7: =G7/R7 -> 65.014577 | V7: =(G7-S7)/G6-1 -> 0.061904762 | W7: =LN((G7-S7)/G6) -> 0.060064241 | X7: n/a | Y7: =LN(E7/E6) -> 0 | Z7: =LN(R7/R6) -> 0.034102638 | AA7: n/a | AB7: FY2016/FY2017 10-K (members); fee income & warehouses from memory - VERIFY
A8: 2016 | B8: 42610 | C8: 52 | D8: 55 | E8: 55 | F8: 110 | G8: 47600 | H8: 10800 | I8: =G8-H8 -> 36800 | J8: 0.39 | K8: =J8*G8 -> 18564 | L8: =K8/G8 -> 0.39 | M8: 86700 | N8: =M8-G8 -> 39100 | O8: 0.9 | P8: 0.88 | Q8: 2646 | R8: 715 | S8: 0 | T8: =Q8*1000/G8 -> 55.588235 | U8: =G8/R8 -> 66.573427 | V8: =(G8-S8)/G7-1 -> 0.067264574 | W8: =LN((G8-S8)/G7) -> 0.065098902 | X8: =Y7 -> 0 | Y8: =LN(E8/E7) -> 0 | Z8: =LN(R8/R7) -> 0.041404915 | AA8: n/a | AB8: FY2016 & FY2018 10-K
A9: 2017 | B9: 42981 | C9: 53 | D9: 55 | E9: 60 | F9: 120 | G9: 49400 | H9: 10800 | I9: =G9-H9 -> 38600 | J9: 0.38 | K9: =J9*G9 -> 18772 | L9: =K9/G9 -> 0.38 | M9: 90300 | N9: =M9-G9 -> 40900 | O9: 0.9 | P9: 0.87 | Q9: 2853 | R9: 741 | S9: 0 | T9: =Q9*1000/G9 -> 57.753036 | U9: =G9/R9 -> 66.666667 | V9: =(G9-S9)/G8-1 -> 0.037815126 | W9: =LN((G9-S9)/G8) -> 0.037117663 | X9: =Y8 -> 0 | Y9: =LN(E9/E8) -> 0.087011377 | Z9: =LN(R9/R8) -> 0.035718083 | AA9: =O9-O8 -> 0 | AB9: FY2017 10-K; fee raised Jun 1, 2017
A10: 2018 | B10: 43345 | C10: 52 | D10: 60 | E10: 60 | F10: 120 | G10: 51600 | H10: 10900 | I10: =G10-H10 -> 40700 | J10: 0.37 | K10: =J10*G10 -> 19092 | L10: =K10/G10 -> 0.37 | M10: 94300 | N10: =M10-G10 -> 42700 | O10: 0.9 | P10: 0.88 | Q10: 3142 | R10: 762 | S10: 0 | T10: =Q10*1000/G10 -> 60.891473 | U10: =G10/R10 -> 67.716535 | V10: =(G10-S10)/G9-1 -> 0.044534413 | W10: =LN((G10-S10)/G9) -> 0.043571248 | X10: =Y9 -> 0.087011377 | Y10: =LN(E10/E9) -> 0 | Z10: =LN(R10/R9) -> 0.02794593 | AA10: =O10-O9 -> 0 | AB10: FY2018 10-K
A11: 2019 | B11: 43709 | C11: 52 | D11: 60 | E11: 60 | F11: 120 | G11: 53900 | H11: 11000 | I11: =G11-H11 -> 42900 | J11: 0.39 | K11: =J11*G11 -> 21021 | L11: =K11/G11 -> 0.39 | M11: 98500 | N11: =M11-G11 -> 44600 | O11: 0.91 | P11: 0.88 | Q11: 3352 | R11: 782 | S11: 0 | T11: =Q11*1000/G11 -> 62.189239 | U11: =G11/R11 -> 68.925831 | V11: =(G11-S11)/G10-1 -> 0.044573643 | W11: =LN((G11-S11)/G10) -> 0.043608805 | X11: =Y10 -> 0 | Y11: =LN(E11/E10) -> 0 | Z11: =LN(R11/R10) -> 0.025908185 | AA11: =O11-O10 -> 0.01 | AB11: FY2019 10-K
A12: 2020 | B12: 44073 | C12: 52 | D12: 60 | E12: 60 | F12: 120 | G12: 58100 | H12: 11300 | I12: =G12-H12 -> 46800 | J12: n/a | K12: 22600 | L12: =K12/G12 -> 0.38898451 | M12: 105500 | N12: =M12-G12 -> 47400 | O12: 0.91 | P12: 0.88 | Q12: 3541 | R12: 795 | S12: 1300 | T12: =Q12*1000/G12 -> 60.946644 | U12: =G12/R12 -> 73.081761 | V12: =(G12-S12)/G11-1 -> 0.05380334 | W12: =LN((G12-S12)/G11) -> 0.052405848 | X12: =Y11 -> 0 | Y12: =LN(E12/E11) -> 0 | Z12: =LN(R12/R11) -> 0.016487374 | AA12: =O12-O11 -> 0 | AB12: FY2020 10-K; counts restated (+1.3M paid)
A13: 2021 | B13: 44437 | C13: 52 | D13: 60 | E13: 60 | F13: 120 | G13: 61700 | H13: 11500 | I13: =G13-H13 -> 50200 | J13: n/a | K13: 25600 | L13: =K13/G13 -> 0.41491086 | M13: 111600 | N13: =M13-G13 -> 49900 | O13: 0.91 | P13: 0.89 | Q13: 3877 | R13: 815 | S13: 0 | T13: =Q13*1000/G13 -> 62.836305 | U13: =G13/R13 -> 75.705521 | V13: =(G13-S13)/G12-1 -> 0.061962134 | W13: =LN((G13-S13)/G12) -> 0.060118267 | X13: =Y12 -> 0 | Y13: =LN(E13/E12) -> 0 | Z13: =LN(R13/R12) -> 0.024845999 | AA13: =O13-O12 -> 0 | AB13: FY2021 10-K
A14: 2022 | B14: 44801 | C14: 52 | D14: 60 | E14: 60 | F14: 120 | G14: 65800 | H14: 11800 | I14: =G14-H14 -> 54000 | J14: n/a | K14: 29100 | L14: =K14/G14 -> 0.44224924 | M14: 118900 | N14: =M14-G14 -> 53100 | O14: 0.93 | P14: 0.9 | Q14: 4224 | R14: 838 | S14: 0 | T14: =Q14*1000/G14 -> 64.194529 | U14: =G14/R14 -> 78.520286 | V14: =(G14-S14)/G13-1 -> 0.066450567 | W14: =LN((G14-S14)/G13) -> 0.064335907 | X14: =Y13 -> 0 | Y14: =LN(E14/E13) -> 0 | Z14: =LN(R14/R13) -> 0.027829987 | AA14: =O14-O13 -> 0.02 | AB14: FY2022 10-K
A15: 2023 | B15: 45172 | C15: 53 | D15: 60 | E15: 60 | F15: 120 | G15: 71000 | H15: 12200 | I15: =G15-H15 -> 58800 | J15: n/a | K15: 32300 | L15: =K15/G15 -> 0.45492958 | M15: 127900 | N15: =M15-G15 -> 56900 | O15: 0.927 | P15: 0.904 | Q15: 4580 | R15: 861 | S15: 0 | T15: =Q15*1000/G15 -> 64.507042 | U15: =G15/R15 -> 82.462253 | V15: =(G15-S15)/G14-1 -> 0.079027356 | W15: =LN((G15-S15)/G14) -> 0.076060039 | X15: =Y14 -> 0 | Y15: =LN(E15/E14) -> 0 | Z15: =LN(R15/R14) -> 0.027076404 | AA15: =O15-O14 -> -0.003 | AB15: FY2023 & FY2025 10-K
A16: 2024 | B16: 45536 | C16: 52 | D16: 60 | E16: 60 | F16: 120 | G16: 76200 | H16: 12500 | I16: =G16-H16 -> 63700 | J16: n/a | K16: 35400 | L16: =K16/G16 -> 0.46456693 | M16: 136800 | N16: =M16-G16 -> 60600 | O16: 0.929 | P16: 0.905 | Q16: 4828 | R16: 890 | S16: 0 | T16: =Q16*1000/G16 -> 63.35958 | U16: =G16/R16 -> 85.617978 | V16: =(G16-S16)/G15-1 -> 0.073239437 | W16: =LN((G16-S16)/G15) -> 0.070681586 | X16: =Y15 -> 0 | Y16: =LN(E16/E15) -> 0 | Z16: =LN(R16/R15) -> 0.033126958 | AA16: =O16-O15 -> 0.002 | AB16: FY2024 & FY2025 10-K
A17: 2025 | B17: 45900 | C17: 52 | D17: 65 | E17: 65 | F17: 130 | G17: 81000 | H17: 12700 | I17: =G17-H17 -> 68300 | J17: n/a | K17: 38700 | L17: =K17/G17 -> 0.47777778 | M17: 145200 | N17: =M17-G17 -> 64200 | O17: 0.923 | P17: 0.898 | Q17: 5323 | R17: 914 | S17: 0 | T17: =Q17*1000/G17 -> 65.716049 | U17: =G17/R17 -> 88.621444 | V17: =(G17-S17)/G16-1 -> 0.062992126 | W17: =LN((G17-S17)/G16) -> 0.061087692 | X17: =Y16 -> 0 | Y17: =LN(E17/E16) -> 0.080042708 | Z17: =LN(R17/R16) -> 0.026609109 | AA17: =O17-O16 -> -0.006 | AB17: FY2025 10-K; fee raised Sep 1, 2024
A19: NOTES
A20: 1. Paid members, Business, cardholders, Executive members, renewal rates and fee income are taken from Costco's 10-K filings (see Sources tab). Gold Star = Paid - Business (matches the 10-K table in every year checked).
A21: 2. FY2014-FY2019 Executive members are an ESTIMATE: Costco reported only a rounded percentage of paid members (39%/39%/39%/38%/37%/39%). FY2020 onward are reported counts.
A22: 3. Series break: in FY2020 Costco standardized its counting method globally, adding ~2.0M cardholders (~1.3M paid members). Levels from FY2020 on include this; FY2019 and earlier were not restated. Column S removes it from the FY2020 growth rate only.
A23: 4. Renewal rates are a trailing measure (renewals 7-18 months before the reporting date). FY2016-FY2022 were published as whole percentages; FY2023 onward to one decimal. FY2014-FY2015 renewal rates not collected (n/a).
A24: 5. Fee columns are the U.S./Canada Gold Star (Individual/Business) fee and the Executive total fee. 'Start of FY' for FY2025 is $65 because the increase took effect Sep 1, 2024, the day before FY2025 began.
A25: 6. Paid-member counts are WORLDWIDE, but the fee changes applied only to the U.S. and Canada, so the fee effect on this demand measure is diluted. The U.S./Canada renewal rate is the cleaner demand proxy.
A26: 7. Warehouse counts for FY2016-FY2022 are derived from the cumulative 'year opened' table in the FY2025 10-K (assumes no closures); FY2023-FY2025 are stated directly. FY2014-FY2015 and fee income for FY2014-FY2015 are from memory and must be checked against the FY2015/FY2016 10-Ks.
A27: 8. FY2017 and FY2023 contain 53 weeks of fee income, which slightly inflates those years' fee income and the following year's growth comparison.

Sheet Fee_History
A1: Costco U.S./Canada Annual Membership Fee Schedule
A2: Gold Star / Business fee and Executive total fee ($). Executive total = base fee + Executive upgrade fee.
A4: Year effective | B4: Effective date | C4: Gold Star / Business fee ($) | D4: Executive total fee ($) | E4: Executive upgrade fee ($) = Exec - GS | F4: Max annual 2% Exec reward ($) | G4: % change, Gold Star | H4: % change, Executive | I4: Years since prior increase (calendar) | J4: Verification / source
A5: 2006 | B5: 2006 (date not collected) | C5: 50 | D5: 100 | E5: =D5-C5 -> 50 | F5: n/a | G5: n/a | H5: n/a | I5: n/a | J5: NOT verified - from memory. Check FY2006/FY2007 10-K.
A6: 2011 | B6: 2011 (date not collected) | C6: 55 | D6: 110 | E6: =D6-C6 -> 55 | F6: 750 | G6: =C6/C5-1 -> 0.1 | H6: =D6/D5-1 -> 0.1 | I6: =A6-A5 -> 5 | J6: GS fee of $55 confirmed indirectly by FY2017 10-K ('increased by $5 to $60'); $750 cap per FY2016 10-K. Exec $110 inferred ($55+$55).
A7: 2017 | B7: 42887 | C7: 60 | D7: 120 | E7: =D7-C7 -> 60 | F7: 1000 | G7: =C7/C6-1 -> 0.090909091 | H7: =D7/D6-1 -> 0.090909091 | I7: =A7-A6 -> 6 | J7: FY2017 10-K: effective June 1, 2017; FY2022 10-K: Exec upgrade fee $60.
A8: 2024 | B8: 45536 | C8: 65 | D8: 130 | E8: =D8-C8 -> 65 | F8: 1250 | G8: =C8/C7-1 -> 0.083333333 | H8: =D8/D7-1 -> 0.083333333 | I8: =A8-A7 -> 7 | J8: FY2024 10-K and Costco announcement: GS $60->$65, Exec $120->$130, reward cap $1,000->$1,250.
A10: Average years between increases (verified + unverified rows) | I10: =AVERAGE(I6:I8) -> 6
A12: Costco has historically raised fees roughly every 5-6 years; the 2017->2024 gap was about 7.25 years (Jun 2017 to Sep 2024).

Sheet Event_Study
A1: Event Study: Membership Growth and Renewal Around Fee Increases
A2: Baseline = average paid-member growth in the 2 fiscal years before the increase. Shortfall = actual cumulative growth in the response window minus baseline x years. Implied arc elasticity = shortfall / % fee change. This is indicative only: warehouse openings, online promotions and the worldwide count all confound it.
A4: Event | B4: Effective date | C4: Event fiscal year | D4: Old Gold Star fee ($) | E4: New Gold Star fee ($) | F4: Fee change, % | G4: Response window (years) [input] | H4: Baseline avg growth (prior 2 yrs) | I4: Actual cum. growth in window | J4: Expected cum. growth at baseline | K4: Shortfall vs. trend | L4: Implied arc elasticity | M4: Renewal rate U.S./Can, year before | N4: Renewal rate U.S./Can, end of window | O4: Change (pts)
A5: June 2017 increase ($55 -> $60) | B5: 42887 | C5: 2017 | D5: =INDEX(Panel_Data!$E$6:$E$17,MATCH(C5-1,Panel_Data!$A$6:$A$17,0)) -> 55 | E5: =INDEX(Panel_Data!$E$6:$E$17,MATCH(C5,Panel_Data!$A$6:$A$17,0)) -> 60 | F5: =E5/D5-1 -> 0.090909091 | G5: 2 | H5: =AVERAGE(INDEX(Panel_Data!$V$6:$V$17,MATCH(C5-2,Panel_Data!$A$6:$A$17,0)):INDEX(Panel_Data!$V$6:$V$17,MATCH(C5-1,Panel_Data!$A$6:$A$17,0))) -> 0.064584668 | I5: =SUM(INDEX(Panel_Data!$V$6:$V$17,MATCH(C5,Panel_Data!$A$6:$A$17,0)):INDEX(Panel_Data!$V$6:$V$17,MATCH(C5+G5-1,Panel_Data!$A$6:$A$17,0))) -> 0.082349539 | J5: =H5*G5 -> 0.12916934 | K5: =I5-J5 -> -0.046819797 | L5: =IF(F5=0,0,K5/F5) -> -0.51501777 | M5: =INDEX(Panel_Data!$O$6:$O$17,MATCH(C5-1,Panel_Data!$A$6:$A$17,0)) -> 0.9 | N5: =INDEX(Panel_Data!$O$6:$O$17,MATCH(C5+G5-1,Panel_Data!$A$6:$A$17,0)) -> 0.9 | O5: =N5-M5 -> 0
A6: Sept 2024 increase ($60 -> $65) | B6: 45536 | C6: 2025 | D6: =INDEX(Panel_Data!$E$6:$E$17,MATCH(C6-1,Panel_Data!$A$6:$A$17,0)) -> 60 | E6: =INDEX(Panel_Data!$E$6:$E$17,MATCH(C6,Panel_Data!$A$6:$A$17,0)) -> 65 | F6: =E6/D6-1 -> 0.083333333 | G6: 1 | H6: =AVERAGE(INDEX(Panel_Data!$V$6:$V$17,MATCH(C6-2,Panel_Data!$A$6:$A$17,0)):INDEX(Panel_Data!$V$6:$V$17,MATCH(C6-1,Panel_Data!$A$6:$A$17,0))) -> 0.076133396 | I6: =SUM(INDEX(Panel_Data!$V$6:$V$17,MATCH(C6,Panel_Data!$A$6:$A$17,0)):INDEX(Panel_Data!$V$6:$V$17,MATCH(C6+G6-1,Panel_Data!$A$6:$A$17,0))) -> 0.062992126 | J6: =H6*G6 -> 0.076133396 | K6: =I6-J6 -> -0.01314127 | L6: =IF(F6=0,0,K6/F6) -> -0.15769524 | M6: =INDEX(Panel_Data!$O$6:$O$17,MATCH(C6-1,Panel_Data!$A$6:$A$17,0)) -> 0.929 | N6: =INDEX(Panel_Data!$O$6:$O$17,MATCH(C6+G6-1,Panel_Data!$A$6:$A$17,0)) -> 0.923 | O6: =N6-M6 -> -0.006
A8: Average implied elasticity (feeds Revenue_Sim) | L8: =AVERAGE(L5:L6) -> -0.3363565
A10: Reading the table: the 2017 hike took effect June 1 (late in FY2017), so the response window is 2 years; the 2024 hike took effect on the first day of FY2025, and FY2026 is not yet in an annual filing, so the window is 1 year. Yellow = window length is an adjustable assumption.

Sheet Regression
A1: Growth-Rate Regressions: Fee Changes and Paid-Member Growth
A2: Log-difference model, so the coefficient on Delta ln(fee) is the elasticity of paid members with respect to the Gold Star fee. Only two fee changes exist in the sample (FY2017, FY2025), so statistical power is very low; treat results as indicative, not conclusive.
A4: Model 1 (FY2015-FY2025): Delta ln(Paid) = a + b1*Delta ln(GS fee, t) + b2*Delta ln(Warehouses)
A5: Variable | B5: Coefficient | C5: Std. error | D5: t-stat | E5: p-value (2-tailed)
A6: Intercept | B6: =INDEX(LINEST(Panel_Data!$W$7:$W$17,Panel_Data!$Y$7:$Z$17,TRUE(),TRUE()),1,3) -> 0.050849627 | C6: =INDEX(LINEST(Panel_Data!$W$7:$W$17,Panel_Data!$Y$7:$Z$17,TRUE(),TRUE()),2,3) -> 0.017796653 | D6: =IF(C6=0,0,B6/C6) -> 2.8572579 | E6: =TDIST(ABS(D6),$B$11,2) -> 0.021240737
A7: Delta ln(GS fee, t) -> elasticity | B7: =INDEX(LINEST(Panel_Data!$W$7:$W$17,Panel_Data!$Y$7:$Z$17,TRUE(),TRUE()),1,2) -> -0.14181082 | C7: =INDEX(LINEST(Panel_Data!$W$7:$W$17,Panel_Data!$Y$7:$Z$17,TRUE(),TRUE()),2,2) -> 0.11782847 | D7: =IF(C7=0,0,B7/C7) -> -1.2035361 | E7: =TDIST(ABS(D7),$B$11,2) -> 0.26317118
A8: Delta ln(Warehouses) | B8: =INDEX(LINEST(Panel_Data!$W$7:$W$17,Panel_Data!$Y$7:$Z$17,TRUE(),TRUE()),1,1) -> 0.30678295 | C8: =INDEX(LINEST(Panel_Data!$W$7:$W$17,Panel_Data!$Y$7:$Z$17,TRUE(),TRUE()),2,1) -> 0.60290593 | D8: =IF(C8=0,0,B8/C8) -> 0.50884049 | E8: =TDIST(ABS(D8),$B$11,2) -> 0.62459741
A9: Observations (n) | B9: =COUNT(Panel_Data!$W$7:$W$17) -> 11
A10: R-squared | B10: =INDEX(LINEST(Panel_Data!$W$7:$W$17,Panel_Data!$Y$7:$Z$17,TRUE(),TRUE()),3,1) -> 0.16228207
A11: Residual degrees of freedom | B11: =INDEX(LINEST(Panel_Data!$W$7:$W$17,Panel_Data!$Y$7:$Z$17,TRUE(),TRUE()),4,2) -> 8
A14: Model 2 (FY2016-FY2025): adds a one-year lag of the fee change (distributed lag)
A15: Variable | B15: Coefficient | C15: Std. error | D15: t-stat | E15: p-value (2-tailed)
A16: Intercept | B16: =INDEX(LINEST(Panel_Data!$W$8:$W$17,Panel_Data!$X$8:$Z$17,TRUE(),TRUE()),1,4) -> 0.052863066 | C16: =INDEX(LINEST(Panel_Data!$W$8:$W$17,Panel_Data!$X$8:$Z$17,TRUE(),TRUE()),2,4) -> 0.018359504 | D16: =IF(C16=0,0,B16/C16) -> 2.8793298 | E16: =TDIST(ABS(D16),$B$22,2) -> 0.02808233
A17: Delta ln(GS fee, t) | B17: =INDEX(LINEST(Panel_Data!$W$8:$W$17,Panel_Data!$X$8:$Z$17,TRUE(),TRUE()),1,2) -> -0.17159418 | C17: =INDEX(LINEST(Panel_Data!$W$8:$W$17,Panel_Data!$X$8:$Z$17,TRUE(),TRUE()),2,2) -> 0.12276449 | D17: =IF(C17=0,0,B17/C17) -> -1.397751 | E17: =TDIST(ABS(D17),$B$22,2) -> 0.21168239
A18: Delta ln(GS fee, t-1) | B18: =INDEX(LINEST(Panel_Data!$W$8:$W$17,Panel_Data!$X$8:$Z$17,TRUE(),TRUE()),1,3) -> -0.21022241 | C18: =INDEX(LINEST(Panel_Data!$W$8:$W$17,Panel_Data!$X$8:$Z$17,TRUE(),TRUE()),2,3) -> 0.15400374 | D18: =IF(C18=0,0,B18/C18) -> -1.3650475 | E18: =TDIST(ABS(D18),$B$22,2) -> 0.22120566
A19: Delta ln(Warehouses) | B19: =INDEX(LINEST(Panel_Data!$W$8:$W$17,Panel_Data!$X$8:$Z$17,TRUE(),TRUE()),1,1) -> 0.32204776 | C19: =INDEX(LINEST(Panel_Data!$W$8:$W$17,Panel_Data!$X$8:$Z$17,TRUE(),TRUE()),2,1) -> 0.63249501 | D19: =IF(C19=0,0,B19/C19) -> 0.50917044 | E19: =TDIST(ABS(D19),$B$22,2) -> 0.62881062
A20: Observations (n) | B20: =COUNT(Panel_Data!$W$8:$W$17) -> 10
A21: R-squared | B21: =INDEX(LINEST(Panel_Data!$W$8:$W$17,Panel_Data!$X$8:$Z$17,TRUE(),TRUE()),3,1) -> 0.358991
A22: Residual degrees of freedom | B22: =INDEX(LINEST(Panel_Data!$W$8:$W$17,Panel_Data!$X$8:$Z$17,TRUE(),TRUE()),4,2) -> 6
A23: Cumulative fee elasticity (t + t-1) | B23: =B17+B18 -> -0.3818166
A25: Notes: (1) A negative elasticity means higher fees reduce membership growth; |elasticity| < 1 means revenue rises with the fee. (2) Paid members are worldwide while fee changes were U.S./Canada only, which biases the estimate toward zero. (3) FY2020 growth is adjusted for the counting-method change. (4) The standard error of the cumulative elasticity is not computed here.

Sheet Revenue_Sim
A1: Membership Revenue Simulator: What Gold Star Fee Maximizes Estimated Fee Income?
A2: Executive fee is assumed to equal the Gold Star fee plus a fixed upgrade fee. Three demand shapes are compared. The elasticity comes from the Event_Study tab unless overridden. ASSUMPTIONS, not estimates: the escalation factor k and the idea that the elasticity holds far outside the observed $55-$65 range.
A4: INPUTS
A5: Base Gold Star fee, P0 ($) | B5: =Panel_Data!E17 -> 65 | C5: FY2025 U.S./Canada fee (Panel_Data)
A6: Executive upgrade fee, U ($) | B6: 65 | C6: FY2025 10-K: $65 upgrade (Exec total $130)
A7: Executive share of paid members, s | B7: =Panel_Data!L17 -> 0.47777778 | C7: FY2025: 38.7M / 81.0M
A8: Fee component moving with P: c = s x U ($) | B8: =B7*B6 -> 31.055556 | C8: Average fee per member = P + c
A9: Base paid members, Q0 (000s) | B9: =Panel_Data!G17 -> 81000 | C9: FY2025
A10: Base membership fee income, R0 ($M) | B10: =Panel_Data!Q17 -> 5323 | C10: FY2025 reported (understates run-rate: fee income is deferred over 12 months)
A11: Memberships affected by fee change (000s) | B11: 52000 | C11: Costco announcement, July 2024: ~52 million memberships (news reports)
A12: Paid members FY2024 (000s) | B12: =Panel_Data!G16 -> 76200 | C12: Denominator for share affected
A13: Share of paid members subject to U.S./Canada fee change, w | B13: =B11/B12 -> 0.6824147 | C13: Count-based approximation
A14: Event-study average elasticity | B14: =Event_Study!L8 -> -0.3363565 | C14: From Event_Study tab
A15: Elasticity OVERRIDE (leave blank to use event-study value) | C15: Type e.g. -0.5 to test; yellow = user input
A16: Elasticity used, e | B16: =IF(ISNUMBER(B15),B15,B14) -> -0.3363565 | C16: d ln(Q) / d ln(P) at the base fee
A17: Elasticity escalation factor, k (Model C) | B17: 2 | C17: ASSUMPTION: elasticity grows as (P/P0)^k; k=0 is constant elasticity
A18: Grid start price ($) | B18: 55 | C18: Lower bound of simulated fees
A19: Grid step ($) | B19: 5 | C19: Increment
A21: CLOSED-FORM RESULT: MODEL B (linear demand through the base point)
A22: Slope of demand, dQ/dP (000s members per $) | B22: =B16*B9/B5 -> -419.15195
A23: Demand intercept a (000s members) | B23: =B9-B22*B5 -> 108244.88
A24: Revenue-maximizing Gold Star fee, P* ($) | B24: =IF(B22>=0,"n/a (demand not downward-sloping)",-(B23+B22*B8)/(2*B22)) -> 113.59589 | C24: Maximizes Q(P) x (P + c); independent of w and R0
A28: PRICE GRID (revenue in $M = R0 x [(1-w) + w x (Q/Q0) x (P+c)/(P0+c)])
A29: Gold Star fee P ($) | B29: Executive fee ($) | C29: A: Members, const. elasticity (000s) | D29: A: Revenue ($M) | E29: B: Members, linear demand (000s) | F29: B: Revenue ($M) | G29: C: Members, rising elasticity (000s) | H29: C: Revenue ($M) | I29: B: Revenue vs. base | J29: C: Revenue vs. base
A30: =B18 -> 55 | B30: =A30+$B$6 -> 120 | C30: =$B$9*(A30/$B$5)^$B$16 -> 85681.667 | D30: =$B$10*((1-$B$13)+$B$13*(C30/$B$9)*(A30+$B$8)/($B$5+$B$8)) -> 5132.9289 | E30: =MAX(0,$B$9+$B$22*(A30-$B$5)) -> 85191.52 | F30: =$B$10*((1-$B$13)+$B$13*(E30/$B$9)*(A30+$B$8)/($B$5+$B$8)) -> 5113.2363 | G30: =$B$9*EXP($B$16/$B$17*((A30/$B$5)^$B$17-1)) -> 84962.991 | H30: =$B$10*((1-$B$13)+$B$13*(G30/$B$9)*(A30+$B$8)/($B$5+$B$8)) -> 5104.0547 | I30: =F30/$B$10-1 -> -0.039407044 | J30: =H30/$B$10-1 -> -0.041131931
A31: =A30+$B$19 -> 60 | B31: =A31+$B$6 -> 125 | C31: =$B$9*(A31/$B$5)^$B$16 -> 83210.375 | D31: =$B$10*((1-$B$13)+$B$13*(C31/$B$9)*(A31+$B$8)/($B$5+$B$8)) -> 5227.8828 | E31: =MAX(0,$B$9+$B$22*(A31-$B$5)) -> 83095.76 | F31: =$B$10*((1-$B$13)+$B$13*(E31/$B$9)*(A31+$B$8)/($B$5+$B$8)) -> 5223.0104 | G31: =$B$9*EXP($B$16/$B$17*((A31/$B$5)^$B$17-1)) -> 83040.43 | H31: =$B$10*((1-$B$13)+$B$13*(G31/$B$9)*(A31+$B$8)/($B$5+$B$8)) -> 5220.6583 | I31: =F31/$B$10-1 -> -0.018784444 | J31: =H31/$B$10-1 -> -0.019226328
A32: =A31+$B$19 -> 65 | B32: =A32+$B$6 -> 130 | C32: =$B$9*(A32/$B$5)^$B$16 -> 81000 | D32: =$B$10*((1-$B$13)+$B$13*(C32/$B$9)*(A32+$B$8)/($B$5+$B$8)) -> 5323 | E32: =MAX(0,$B$9+$B$22*(A32-$B$5)) -> 81000 | F32: =$B$10*((1-$B$13)+$B$13*(E32/$B$9)*(A32+$B$8)/($B$5+$B$8)) -> 5323 | G32: =$B$9*EXP($B$16/$B$17*((A32/$B$5)^$B$17-1)) -> 81000 | H32: =$B$10*((1-$B$13)+$B$13*(G32/$B$9)*(A32+$B$8)/($B$5+$B$8)) -> 5323 | I32: =F32/$B$10-1 -> 0 | J32: =H32/$B$10-1 -> 0
A33: =A32+$B$19 -> 70 | B33: =A33+$B$6 -> 135 | C33: =$B$9*(A33/$B$5)^$B$16 -> 79005.894 | D33: =$B$10*((1-$B$13)+$B$13*(C33/$B$9)*(A33+$B$8)/($B$5+$B$8)) -> 5418.0011 | E33: =MAX(0,$B$9+$B$22*(A33-$B$5)) -> 78904.24 | F33: =$B$10*((1-$B$13)+$B$13*(E33/$B$9)*(A33+$B$8)/($B$5+$B$8)) -> 5413.2051 | G33: =$B$9*EXP($B$16/$B$17*((A33/$B$5)^$B$17-1)) -> 78852.612 | H33: =$B$10*((1-$B$13)+$B$13*(G33/$B$9)*(A33+$B$8)/($B$5+$B$8)) -> 5410.7693 | I33: =F33/$B$10-1 -> 0.016946288 | J33: =H33/$B$10-1 -> 0.016488686
A34: =A33+$B$19 -> 75 | B34: =A34+$B$6 -> 140 | C34: =$B$9*(A34/$B$5)^$B$16 -> 77193.577 | D34: =$B$10*((1-$B$13)+$B$13*(C34/$B$9)*(A34+$B$8)/($B$5+$B$8)) -> 5512.6935 | E34: =MAX(0,$B$9+$B$22*(A34-$B$5)) -> 76808.48 | F34: =$B$10*((1-$B$13)+$B$13*(E34/$B$9)*(A34+$B$8)/($B$5+$B$8)) -> 5493.6257 | G34: =$B$9*EXP($B$16/$B$17*((A34/$B$5)^$B$17-1)) -> 76609.528 | H34: =$B$10*((1-$B$13)+$B$13*(G34/$B$9)*(A34+$B$8)/($B$5+$B$8)) -> 5483.7747 | I34: =F34/$B$10-1 -> 0.03205442 | J34: =H34/$B$10-1 -> 0.030203769
A35: =A34+$B$19 -> 80 | B35: =A35+$B$6 -> 145 | C35: =$B$9*(A35/$B$5)^$B$16 -> 75535.92 | D35: =$B$10*((1-$B$13)+$B$13*(C35/$B$9)*(A35+$B$8)/($B$5+$B$8)) -> 5606.9435 | E35: =MAX(0,$B$9+$B$22*(A35-$B$5)) -> 74712.721 | F35: =$B$10*((1-$B$13)+$B$13*(E35/$B$9)*(A35+$B$8)/($B$5+$B$8)) -> 5564.2618 | G35: =$B$9*EXP($B$16/$B$17*((A35/$B$5)^$B$17-1)) -> 74282.262 | H35: =$B$10*((1-$B$13)+$B$13*(G35/$B$9)*(A35+$B$8)/($B$5+$B$8)) -> 5541.943 | I35: =F35/$B$10-1 -> 0.045324397 | J35: =H35/$B$10-1 -> 0.041131512
A36: =A35+$B$19 -> 85 | B36: =A36+$B$6 -> 150 | C36: =$B$9*(A36/$B$5)^$B$16 -> 74011.228 | D36: =$B$10*((1-$B$13)+$B$13*(C36/$B$9)*(A36+$B$8)/($B$5+$B$8)) -> 5700.659 | E36: =MAX(0,$B$9+$B$22*(A36-$B$5)) -> 72616.961 | F36: =$B$10*((1-$B$13)+$B$13*(E36/$B$9)*(A36+$B$8)/($B$5+$B$8)) -> 5625.1133 | G36: =$B$9*EXP($B$16/$B$17*((A36/$B$5)^$B$17-1)) -> 71882.486 | H36: =$B$10*((1-$B$13)+$B$13*(G36/$B$9)*(A36+$B$8)/($B$5+$B$8)) -> 5585.3173 | I36: =F36/$B$10-1 -> 0.056756217 | J36: =H36/$B$10-1 -> 0.049279965
A37: =A36+$B$19 -> 90 | B37: =A37+$B$6 -> 155 | C37: =$B$9*(A37/$B$5)^$B$16 -> 72601.909 | D37: =$B$10*((1-$B$13)+$B$13*(C37/$B$9)*(A37+$B$8)/($B$5+$B$8)) -> 5793.7766 | E37: =MAX(0,$B$9+$B$22*(A37-$B$5)) -> 70521.201 | F37: =$B$10*((1-$B$13)+$B$13*(E37/$B$9)*(A37+$B$8)/($B$5+$B$8)) -> 5676.1804 | G37: =$B$9*EXP($B$16/$B$17*((A37/$B$5)^$B$17-1)) -> 69421.931 | H37: =$B$10*((1-$B$13)+$B$13*(G37/$B$9)*(A37+$B$8)/($B$5+$B$8)) -> 5614.0525 | I37: =F37/$B$10-1 -> 0.066349881 | J37: =H37/$B$10-1 -> 0.054678292
A38: =A37+$B$19 -> 95 | B38: =A38+$B$6 -> 160 | C38: =$B$9*(A38/$B$5)^$B$16 -> 71293.514 | D38: =$B$10*((1-$B$13)+$B$13*(C38/$B$9)*(A38+$B$8)/($B$5+$B$8)) -> 5886.254 | E38: =MAX(0,$B$9+$B$22*(A38-$B$5)) -> 68425.441 | F38: =$B$10*((1-$B$13)+$B$13*(E38/$B$9)*(A38+$B$8)/($B$5+$B$8)) -> 5717.463 | G38: =$B$9*EXP($B$16/$B$17*((A38/$B$5)^$B$17-1)) -> 66912.295 | H38: =$B$10*((1-$B$13)+$B$13*(G38/$B$9)*(A38+$B$8)/($B$5+$B$8)) -> 5628.4117 | I38: =F38/$B$10-1 -> 0.074105389 | J38: =H38/$B$10-1 -> 0.057375861
A39: =A38+$B$19 -> 100 | B39: =A39+$B$6 -> 165 | C39: =$B$9*(A39/$B$5)^$B$16 -> 70074.049 | D39: =$B$10*((1-$B$13)+$B$13*(C39/$B$9)*(A39+$B$8)/($B$5+$B$8)) -> 5978.0643 | E39: =MAX(0,$B$9+$B$22*(A39-$B$5)) -> 66329.682 | F39: =$B$10*((1-$B$13)+$B$13*(E39/$B$9)*(A39+$B$8)/($B$5+$B$8)) -> 5748.9611 | G39: =$B$9*EXP($B$16/$B$17*((A39/$B$5)^$B$17-1)) -> 64365.152 | H39: =$B$10*((1-$B$13)+$B$13*(G39/$B$9)*(A39+$B$8)/($B$5+$B$8)) -> 5628.7592 | I39: =F39/$B$10-1 -> 0.080022742 | J39: =H39/$B$10-1 -> 0.057441134
A40: =A39+$B$19 -> 105 | B40: =A40+$B$6 -> 170 | C40: =$B$9*(A40/$B$5)^$B$16 -> 68933.456 | D40: =$B$10*((1-$B$13)+$B$13*(C40/$B$9)*(A40+$B$8)/($B$5+$B$8)) -> 6069.1911 | E40: =MAX(0,$B$9+$B$22*(A40-$B$5)) -> 64233.922 | F40: =$B$10*((1-$B$13)+$B$13*(E40/$B$9)*(A40+$B$8)/($B$5+$B$8)) -> 5770.6746 | G40: =$B$9*EXP($B$16/$B$17*((A40/$B$5)^$B$17-1)) -> 61791.866 | H40: =$B$10*((1-$B$13)+$B$13*(G40/$B$9)*(A40+$B$8)/($B$5+$B$8)) -> 5615.5541 | I40: =F40/$B$10-1 -> 0.084101938 | J40: =H40/$B$10-1 -> 0.054960376
A41: =A40+$B$19 -> 110 | B41: =A41+$B$6 -> 175 | C41: =$B$9*(A41/$B$5)^$B$16 -> 67863.228 | D41: =$B$10*((1-$B$13)+$B$13*(C41/$B$9)*(A41+$B$8)/($B$5+$B$8)) -> 6159.6268 | E41: =MAX(0,$B$9+$B$22*(A41-$B$5)) -> 62138.162 | F41: =$B$10*((1-$B$13)+$B$13*(E41/$B$9)*(A41+$B$8)/($B$5+$B$8)) -> 5782.6037 | G41: =$B$9*EXP($B$16/$B$17*((A41/$B$5)^$B$17-1)) -> 59203.509 | H41: =$B$10*((1-$B$13)+$B$13*(G41/$B$9)*(A41+$B$8)/($B$5+$B$8)) -> 5589.3426 | I41: =F41/$B$10-1 -> 0.086342978 | J41: =H41/$B$10-1 -> 0.05003619
A42: =A41+$B$19 -> 115 | B42: =A42+$B$6 -> 180 | C42: =$B$9*(A42/$B$5)^$B$16 -> 66856.109 | D42: =$B$10*((1-$B$13)+$B$13*(C42/$B$9)*(A42+$B$8)/($B$5+$B$8)) -> 6249.3692 | E42: =MAX(0,$B$9+$B$22*(A42-$B$5)) -> 60042.402 | F42: =$B$10*((1-$B$13)+$B$13*(E42/$B$9)*(A42+$B$8)/($B$5+$B$8)) -> 5784.7482 | G42: =$B$9*EXP($B$16/$B$17*((A42/$B$5)^$B$17-1)) -> 56610.791 | H42: =$B$10*((1-$B$13)+$B$13*(G42/$B$9)*(A42+$B$8)/($B$5+$B$8)) -> 5550.7495 | I42: =F42/$B$10-1 -> 0.086745863 | J42: =H42/$B$10-1 -> 0.042785929
... A46: =A45+$B$19 -> 135 | B46: =A46+$B$6 -> 200 | C46: =$B$9*(A46/$B$5)^$B$16 -> 63345.913 | D46: =$B$10*((1-$B$13)+$B$13*(C46/$B$9)*(A46+$B$8)/($B$5+$B$8)) -> 6601.4998 | E46: =MAX(0,$B$9+$B$22*(A46-$B$5)) -> 51659.363 | F46: =$B$10*((1-$B$13)+$B$13*(E46/$B$9)*(A46+$B$8)/($B$5+$B$8)) -> 5695.4814 | G46: =$B$9*EXP($B$16/$B$17*((A46/$B$5)^$B$17-1)) -> 46394.091 | H46: =$B$10*((1-$B$13)+$B$13*(G46/$B$9)*(A46+$B$8)/($B$5+$B$8)) -> 5287.2827 | I46: =F46/$B$10-1 -> 0.06997584 | J46: =H46/$B$10-1 -> -0.0067099863
A48: GRID RESULTS: price with highest revenue
A49: Model A (constant elasticity) | B49: =IF(MATCH(MAX(D30:D46),D30:D46,0)=17,"No interior max (rises through grid)",INDEX($A$30:$A$46,MATCH(MAX(D30:D46),D30:D46,0))) -> No interior max (rises through grid) | C49: =MAX(D30:D46) -> 6601.4998
...

Sheet Sources
A1: Sources
A3: Item | B3: Fiscal years | C3: Source | D3: URL / notes
A4: 10-K (members, renewal, fee income, warehouses) | B4: FY2025 (also FY2023-FY2024 comparatives) | C4: Costco Form 10-K, FY ended Aug 31, 2025 | D4: https://www.sec.gov/Archives/edgar/data/909832/000090983225000101/cost-20250831.htm
A5: 10-K | B5: FY2024 | C5: Costco Form 10-K, FY ended Sep 1, 2024 | D5: https://www.sec.gov/Archives/edgar/data/909832/000090983224000049/cost-20240901.htm
A6: 10-K | B6: FY2023 | C6: Costco Form 10-K, FY ended Sep 3, 2023 | D6: https://www.sec.gov/Archives/edgar/data/909832/000090983223000042/cost-20230903.htm
A7: 10-K | B7: FY2022 | C7: Costco Form 10-K, FY ended Aug 28, 2022 | D7: https://www.sec.gov/Archives/edgar/data/909832/000090983222000021/cost-20220828.htm
A8: 10-K | B8: FY2021 | C8: Costco Form 10-K, FY ended Aug 29, 2021 | D8: https://www.sec.gov/Archives/edgar/data/909832/000090983221000014/cost-20210829.htm
A9: 10-K | B9: FY2020 | C9: Costco Form 10-K, FY ended Aug 30, 2020 | D9: https://www.sec.gov/Archives/edgar/data/909832/000090983220000017/cost-20200830.htm
A10: 10-K | B10: FY2019 | C10: Costco Form 10-K, FY ended Sep 1, 2019 | D10: https://www.sec.gov/Archives/edgar/data/909832/000090983219000019/cost10k9119.htm
A11: 10-K | B11: FY2018 | C11: Costco Form 10-K, FY ended Sep 2, 2018 | D11: https://www.sec.gov/Archives/edgar/data/0000909832/000090983218000013/cost10k9218.htm
A12: 10-K | B12: FY2017 | C12: Costco Form 10-K, FY ended Sep 3, 2017 | D12: https://www.sec.gov/Archives/edgar/data/0000909832/000090983217000014/cost10k90317.htm
A13: 10-K (FY2014-FY2016 members & Executive %) | B13: FY2014-FY2016 | C13: Costco Form 10-K, FY ended Aug 28, 2016 | D13: https://www.sec.gov/Archives/edgar/data/0000909832/000090983216000032/cost10k82816.htm
A14: 2024 fee increase announcement coverage | B14: FY2025 | C14: AP / NBC / Chain Store Age (July 2024): $60->$65, $120->$130, ~52M memberships affected | D14: https://www.foxla.com/news/costco-raising-membership-fees-1st-time-since-2017
A15: NOT VERIFIED (from memory) | B15: FY2014-FY2015 fee income and warehouses; 2006 and 2011 fee levels | C15: Check FY2015/FY2016 10-K (fee income, warehouse counts) and FY2006/FY2011 10-Ks (fees) | D15: Orange-filled cells in Panel_Data and Fee_History
